# 基本用法
async函数返回一个Promise对象，可以使用then方法添加回调函数。当函数执行的时候，一旦遇到await就会先返回，等到异步操作完成，再接着执行函数体内后面的语句  

```
//函数声明
async function foo(){}

//函数表达式
const foo = async function(){};

//对象的方法
let obj = {async foo(){}};
obj.foo().then(...)

//Class方法
class Storage{
    constructor(){
        this.cachePromise = caches.open('avatars');
    }

    async getAvatar(name){
        const cache = await this.cachePromise;
        return cache.match(`/avatars/${name}.jpg`);
    }
}

const storage = new Storage();
storage.getAvatar('jake').then(...);

//箭头函数
const foo = async ()=>{};
```

## 返回Promise对象
async函数返回一个 Promise 对象。

async函数内部return语句返回的值，会成为then方法回调函数的参数。

```
async function f(){
    return 'hello world';
}

f().then(v => console.log(v));
// "hello world"
```
async函数内部抛出错误，会导致返回的 Promise 对象变为reject状态。抛出的错误对象会被catch方法回调函数接收到。

```
async function f(){
    throw new Error('出错了');
}

f().then(
    v => console.log(v),
    e => console.log(e)
)
// Error: 出错了
```

## Promise对象的状态变化
async函数返回的 Promise 对象，必须等到内部所有await命令后面的 Promise 对象执行完，才会发生状态改变，除非遇到return语句或者抛出错误。也就是说，只有async函数内部的异步操作执行完，才会执行then方法指定的回调函数。

```
async function getTitle(url) {
  let response = await fetch(url);
  let html = await response.text();
  return html.match(/<title>([\s\S]+)<\/title>/i)[1];
}
getTitle('https://tc39.github.io/ecma262/').then(console.log)
// "ECMAScript 2017 Language Specification"
```

上面代码中，函数getTitle内部有三个操作：抓取网页、取出文本、匹配页面标题。只有这三个操作全部完成，才会执行then方法里面的console.log。  

## await命令
正常情况下，await命令后面是一个 Promise 对象，返回该对象的结果。如果不是 Promise 对象，就直接返回对应的值。  

```
async function f(){
    return await 123;
    //等同于return 123
}

f().then(v=>console.log(v));
```
借助await命令就可以让程序停顿指定的时间。 

```
function sleep(interval){
    return new Promise(resolve=>{
        setTimeout(resolve,interval);
    })
}

//用法
async function one2FiveInAsync(){
    for(let i=1;i<=5;i++){
        console.log(i);
        await sleep(1000);
    }
} 

one2FiveInAsync()
```
任何一个await语句后面的 Promise 对象变为reject状态，那么整个async函数都会中断执行。
```
async function f(){
    await Promise.reject('出错了');
    await Promise.resolve('hello world');//不会执行
}
```
我们希望即使前一个异步操作失败，也不要中断后面的异步操作。这时可以将第一个await放在try...catch结构里面，这样不管这个异步操作是否成功，第二个await都会执行。

```
async function f(){
    try{
        await Promise.reject('出错了');
    }catch(e){

    }
    return await Promise.resolve('hello world');
}

f().then(v => console.log(v));
//hello world
```
另一种方法是await后面的 Promise 对象再跟一个catch方法，处理前面可能出现的错误。

```
async function f(){
    await Promise.reject('出错了').catch(e=>console.log(e));
    return await Promise.resolve('hello world');
}

f().then(v => console.log(v));
//出错了
//hello world
```

## 错误处理
如果await后面的异步操作出错，那么等同于async函数返回的 Promise 对象被reject。

```
async function f(){
    await new Promise(function(resolve,reject){
        throw new Error('出错了');
    });
}

f().then(v=>console.log(v)).catch(e=>console.log(e));
//Error:出错了
```
防止出错的方法，也是将其放在try...catch代码块之中。

```
const superagent = require('superagent');
const NUM_RETRIES = 3;

async function test(){
    let i;
    for(i=0;i<NUM_RETRIES;++i){
        try{
            await superagent.get('http://google.com/this-throws-an-error');
            break;
        }catch(err){}
    }
    console.log(i);//3
}

test();
```
上面代码中，如果await操作成功，就会使用break语句退出循环；如果失败，会被catch语句捕捉，然后进入下一轮循环。